Workbook

Sheet Analysis dashboard
A1: Placement Statistics
A2: SECTION | B2: TOTAL | C2: BOYS | D2: GIRLS | E2: ELIGIBLE | F2: BOYS | G2: GIRLS | H2: PLACED UNIQUE | I2: BOYS | J2: GIRLS | K2: PLACED (Total offers) | L2: Boys(total multiple offers) | M2: girls (total multiple offers) | N2: Total students having multiple offers | O2: Boys | P2: Girls | Q2: Unplaced Students | R2: Boys | S2: Girls
A3: A | B3: =COUNTIF('Analysis data'!$C:$C,$A$3) -> 72 | C3: =COUNTIFS('Analysis data'!$C:$C,$A$3,'Analysis data'!$H:$H,"male") -> 47 | D3: =COUNTIFS('Analysis data'!$C:$C,$A$3,'Analysis data'!$H:$H,"female") -> 25 | E3: =COUNTIFS('Analysis data'!$C:$C,$A$3,'Analysis data'!$G:$G,"pass") -> 59 | F3: =COUNTIFS('Analysis data'!$C:$C,$A$3,'Analysis data'!$H:$H,"male",'Analysis data'!$G:$G,"pass") -> 37 | G3: =COUNTIFS('Analysis data'!$C:$C,$A$3,'Analysis data'!$H:$H,"female",'Analysis data'!$G:$G,"pass") -> 22 | H3: =COUNTIFS('Analysis data'!$C:$C,$A$3,'Analysis data'!$L:$L,"<>0") -> 53 | I3: =COUNTIFS('Analysis data'!$C:$C,$A$3,'Analysis data'!$L:$L,"<>0",'Analysis data'!$H:$H,"male") -> 36 | J3: =COUNTIFS('Analysis data'!$C:$C,$A$3,'Analysis data'!$L:$L,"<>0",'Analysis data'!$H:$H,"FEmale") -> 17 | K3: =SUMIFS('Analysis data'!$L$2:$L$358,'Analysis data'!$C$2:$C$358,"a",'Analysis data'!$L$2:$L$358,">0") -> 104 | L3: =SUMIFS('Analysis data'!$L$2:$L$358,'Analysis data'!$C$2:$C$358,"a",'Analysis data'!$H$2:$H$358,"male",'Analysis data'!$L$2:$L$358,">0") -> 70 | M3: =SUMIFS('Analysis data'!$L$2:$L$358,'Analysis data'!$C$2:$C$358,"a",'Analysis data'!$H$2:$H$358,"female",'Analysis data'!$L$2:$L$358,">0") -> 34 | N3: =COUNTIFS('Analysis data'!$C$2:$C$358,"A",'Analysis data'!$L$2:$L$358,">1") -> 29 | O3: =COUNTIFS('Analysis data'!$C$2:$C$358,"A",'Analysis data'!$L$2:$L$358,">1",'Analysis data'!$H$2:$H$358,"male") -> 21 | P3: =COUNTIFS('Analysis data'!$C$2:$C$358,"A",'Analysis data'!$L$2:$L$358,">1",'Analysis data'!$H$2:$H$358,"female") -> 8 | Q3: =COUNTIFS('Analysis data'!$C:$C,$A$3,'Analysis data'!$G:$G,"pass",'Analysis data'!$L:$L,"0") -> 10 | R3: =COUNTIFS('Analysis data'!$C:$C,$A$3,'Analysis data'!$G:$G,"pass",'Analysis data'!$L:$L,"0",'Analysis data'!$H:$H,"male") -> 5 | S3: =COUNTIFS('Analysis data'!$C:$C,$A$3,'Analysis data'!$G:$G,"pass",'Analysis data'!$L:$L,"0",'Analysis data'!$H:$H,"FEmale") -> 5
A4: B | B4: =COUNTIF('Analysis data'!$C:$C,$A$4) -> 72 | C4: =COUNTIFS('Analysis data'!$C:$C,$A$4,'Analysis data'!$H:$H,"male") -> 44 | D4: =COUNTIFS('Analysis data'!$C:$C,$A$4,'Analysis data'!$H:$H,"female") -> 28 | E4: =COUNTIFS('Analysis data'!$C:$C,$A$4,'Analysis data'!$G:$G,"pass") -> 60 | F4: =COUNTIFS('Analysis data'!$C:$C,$A$4,'Analysis data'!$H:$H,"male",'Analysis data'!$G:$G,"pass") -> 33 | G4: =COUNTIFS('Analysis data'!$C:$C,$A$4,'Analysis data'!$H:$H,"female",'Analysis data'!$G:$G,"pass") -> 27 | H4: =COUNTIFS('Analysis data'!$C:$C,$A$4,'Analysis data'!$L:$L,"<>0") -> 50 | I4: =COUNTIFS('Analysis data'!$C:$C,$A$4,'Analysis data'!$L:$L,"<>0",'Analysis data'!$H:$H,"male") -> 29 | J4: =COUNTIFS('Analysis data'!$C:$C,$A$4,'Analysis data'!$L:$L,"<>0",'Analysis data'!$H:$H,"FEmale") -> 21 | K4: =SUMIFS('Analysis data'!$L$2:$L$358,'Analysis data'!$C$2:$C$358,"b",'Analysis data'!$L$2:$L$358,">0") -> 100 | L4: =SUMIFS('Analysis data'!$L$2:$L$358,'Analysis data'!$C$2:$C$358,"b",'Analysis data'!$H$2:$H$358,"male",'Analysis data'!$L$2:$L$358,">0") -> 58 | M4: =SUMIFS('Analysis data'!$L$2:$L$358,'Analysis data'!$C$2:$C$358,"b",'Analysis data'!$H$2:$H$358,"female",'Analysis data'!$L$2:$L$358,">0") -> 42 | N4: =COUNTIFS('Analysis data'!$C$2:$C$358,"b",'Analysis data'!$L$2:$L$358,">1") -> 30 | O4: =COUNTIFS('Analysis data'!$C$2:$C$358,"b",'Analysis data'!$L$2:$L$358,">1",'Analysis data'!$H$2:$H$358,"male") -> 17 | P4: =COUNTIFS('Analysis data'!$C$2:$C$358,"b",'Analysis data'!$L$2:$L$358,">1",'Analysis data'!$H$2:$H$358,"female") -> 13 | Q4: =COUNTIFS('Analysis data'!$C:$C,$A$4,'Analysis data'!$G:$G,"pass",'Analysis data'!$L:$L,"0") -> 12 | R4: =COUNTIFS('Analysis data'!$C:$C,$A$4,'Analysis data'!$G:$G,"pass",'Analysis data'!$L:$L,"0",'Analysis data'!$H:$H,"male") -> 6 | S4: =COUNTIFS('Analysis data'!$C:$C,$A$4,'Analysis data'!$G:$G,"pass",'Analysis data'!$L:$L,"0",'Analysis data'!$H:$H,"FEmale") -> 6
A5: C | B5: =COUNTIF('Analysis data'!$C:$C,$A$5) -> 71 | C5: =COUNTIFS('Analysis data'!$C:$C,$A$5,'Analysis data'!$H:$H,"male") -> 49 | D5: =COUNTIFS('Analysis data'!$C:$C,$A$5,'Analysis data'!$H:$H,"female") -> 22 | E5: =COUNTIFS('Analysis data'!$C:$C,$A$5,'Analysis data'!$G:$G,"pass") -> 57 | F5: =COUNTIFS('Analysis data'!$C:$C,$A$5,'Analysis data'!$H:$H,"male",'Analysis data'!$G:$G,"pass") -> 38 | G5: =COUNTIFS('Analysis data'!$C:$C,$A$5,'Analysis data'!$H:$H,"female",'Analysis data'!$G:$G,"pass") -> 19 | H5: =COUNTIFS('Analysis data'!$C:$C,$A$5,'Analysis data'!$L:$L,"<>0") -> 54 | I5: =COUNTIFS('Analysis data'!$C:$C,$A$5,'Analysis data'!$L:$L,"<>0",'Analysis data'!$H:$H,"male") -> 36 | J5: =COUNTIFS('Analysis data'!$C:$C,$A$5,'Analysis data'!$L:$L,"<>0",'Analysis data'!$H:$H,"FEmale") -> 18 | K5: =SUMIFS('Analysis data'!$L$2:$L$358,'Analysis data'!$C$2:$C$358,"c",'Analysis data'!$L$2:$L$358,">0") -> 95 | L5: =SUMIFS('Analysis data'!$L$2:$L$358,'Analysis data'!$C$2:$C$358,"c",'Analysis data'!$H$2:$H$358,"male",'Analysis data'!$L$2:$L$358,">0") -> 65 | M5: =SUMIFS('Analysis data'!$L$2:$L$358,'Analysis data'!$C$2:$C$358,"c",'Analysis data'!$H$2:$H$358,"female",'Analysis data'!$L$2:$L$358,">0") -> 30 | N5: =COUNTIFS('Analysis data'!$C$2:$C$358,"c",'Analysis data'!$L$2:$L$358,">1") -> 30 | O5: =COUNTIFS('Analysis data'!$C$2:$C$358,"c",'Analysis data'!$L$2:$L$358,">1",'Analysis data'!$H$2:$H$358,"male") -> 20 | P5: =COUNTIFS('Analysis data'!$C$2:$C$358,"c",'Analysis data'!$L$2:$L$358,">1",'Analysis data'!$H$2:$H$358,"female") -> 10 | Q5: =COUNTIFS('Analysis data'!$C:$C,$A$5,'Analysis data'!$G:$G,"pass",'Analysis data'!$L:$L,"0") -> 6 | R5: =COUNTIFS('Analysis data'!$C:$C,$A$5,'Analysis data'!$G:$G,"pass",'Analysis data'!$L:$L,"0",'Analysis data'!$H:$H,"male") -> 4 | S5: =COUNTIFS('Analysis data'!$C:$C,$A$5,'Analysis data'!$G:$G,"pass",'Analysis data'!$L:$L,"0",'Analysis data'!$H:$H,"FEmale") -> 2
A6: D | B6: =COUNTIF('Analysis data'!$C:$C,$A$6) -> 71 | C6: =COUNTIFS('Analysis data'!$C:$C,$A$6,'Analysis data'!$H:$H,"male") -> 37 | D6: =COUNTIFS('Analysis data'!$C:$C,$A$6,'Analysis data'!$H:$H,"female") -> 34 | E6: =COUNTIFS('Analysis data'!$C:$C,$A$6,'Analysis data'!$G:$G,"pass") -> 63 | F6: =COUNTIFS('Analysis data'!$C:$C,$A$6,'Analysis data'!$H:$H,"male",'Analysis data'!$G:$G,"pass") -> 31 | G6: =COUNTIFS('Analysis data'!$C:$C,$A$6,'Analysis data'!$H:$H,"female",'Analysis data'!$G:$G,"pass") -> 32 | H6: =COUNTIFS('Analysis data'!$C:$C,$A$6,'Analysis data'!$L:$L,"<>0") -> 49 | I6: =COUNTIFS('Analysis data'!$C:$C,$A$6,'Analysis data'!$L:$L,"<>0",'Analysis data'!$H:$H,"male") -> 23 | J6: =COUNTIFS('Analysis data'!$C:$C,$A$6,'Analysis data'!$L:$L,"<>0",'Analysis data'!$H:$H,"FEmale") -> 26 | K6: =SUMIFS('Analysis data'!$L$2:$L$358,'Analysis data'!$C$2:$C$358,"d",'Analysis data'!$L$2:$L$358,">0") -> 94 | L6: =SUMIFS('Analysis data'!$L$2:$L$358,'Analysis data'!$C$2:$C$358,"d",'Analysis data'!$H$2:$H$358,"male",'Analysis data'!$L$2:$L$358,">0") -> 42 | M6: =SUMIFS('Analysis data'!$L$2:$L$358,'Analysis data'!$C$2:$C$358,"d",'Analysis data'!$H$2:$H$358,"female",'Analysis data'!$L$2:$L$358,">0") -> 52 | N6: =COUNTIFS('Analysis data'!$C$2:$C$358,"d",'Analysis data'!$L$2:$L$358,">1") -> 28 | O6: =COUNTIFS('Analysis data'!$C$2:$C$358,"d",'Analysis data'!$L$2:$L$358,">1",'Analysis data'!$H$2:$H$358,"male") -> 12 | P6: =COUNTIFS('Analysis data'!$C$2:$C$358,"d",'Analysis data'!$L$2:$L$358,">1",'Analysis data'!$H$2:$H$358,"female") -> 16 | Q6: =COUNTIFS('Analysis data'!$C:$C,$A$6,'Analysis data'!$G:$G,"pass",'Analysis data'!$L:$L,"0") -> 16 | R6: =COUNTIFS('Analysis data'!$C:$C,$A$6,'Analysis data'!$G:$G,"pass",'Analysis data'!$L:$L,"0",'Analysis data'!$H:$H,"male") -> 9 | S6: =COUNTIFS('Analysis data'!$C:$C,$A$6,'Analysis data'!$G:$G,"pass",'Analysis data'!$L:$L,"0",'Analysis data'!$H:$H,"FEmale") -> 7
A7: E | B7: =COUNTIF('Analysis data'!$C:$C,$A$7) -> 71 | C7: =COUNTIFS('Analysis data'!$C:$C,$A$7,'Analysis data'!$H:$H,"male") -> 44 | D7: =COUNTIFS('Analysis data'!$C:$C,$A$7,'Analysis data'!$H:$H,"female") -> 27 | E7: =COUNTIFS('Analysis data'!$C:$C,$A$7,'Analysis data'!$G:$G,"pass") -> 62 | F7: =COUNTIFS('Analysis data'!$C:$C,$A$7,'Analysis data'!$H:$H,"male",'Analysis data'!$G:$G,"pass") -> 36 | G7: =COUNTIFS('Analysis data'!$C:$C,$A$7,'Analysis data'!$H:$H,"female",'Analysis data'!$G:$G,"pass") -> 26 | H7: =COUNTIFS('Analysis data'!$C:$C,$A$7,'Analysis data'!$L:$L,"<>0") -> 53 | I7: =COUNTIFS('Analysis data'!$C:$C,$A$7,'Analysis data'!$L:$L,"<>0",'Analysis data'!$H:$H,"male") -> 31 | J7: =COUNTIFS('Analysis data'!$C:$C,$A$7,'Analysis data'!$L:$L,"<>0",'Analysis data'!$H:$H,"FEmale") -> 22 | K7: =SUMIFS('Analysis data'!$L$2:$L$358,'Analysis data'!$C$2:$C$358,"e",'Analysis data'!$L$2:$L$358,">0") -> 111 | L7: =SUMIFS('Analysis data'!$L$2:$L$358,'Analysis data'!$C$2:$C$358,"e",'Analysis data'!$H$2:$H$358,"male",'Analysis data'!$L$2:$L$358,">0") -> 60 | M7: =SUMIFS('Analysis data'!$L$2:$L$358,'Analysis data'!$C$2:$C$358,"e",'Analysis data'!$H$2:$H$358,"female",'Analysis data'!$L$2:$L$358,">0") -> 51 | N7: =COUNTIFS('Analysis data'!$C$2:$C$358,"e",'Analysis data'!$L$2:$L$358,">1") -> 32 | O7: =COUNTIFS('Analysis data'!$C$2:$C$358,"e",'Analysis data'!$L$2:$L$358,">1",'Analysis data'!$H$2:$H$358,"male") -> 16 | P7: =COUNTIFS('Analysis data'!$C$2:$C$358,"e",'Analysis data'!$L$2:$L$358,">1",'Analysis data'!$H$2:$H$358,"female") -> 16 | Q7: =COUNTIFS('Analysis data'!$C:$C,$A$7,'Analysis data'!$G:$G,"pass",'Analysis data'!$L:$L,"0") -> 10 | R7: =COUNTIFS('Analysis data'!$C:$C,$A$7,'Analysis data'!$G:$G,"pass",'Analysis data'!$L:$L,"0",'Analysis data'!$H:$H,"male") -> 6 | S7: =COUNTIFS('Analysis data'!$C:$C,$A$7,'Analysis data'!$G:$G,"pass",'Analysis data'!$L:$L,"0",'Analysis data'!$H:$H,"FEmale") -> 4
B8: =SUM(B3:B7) -> 357 | C8: =SUM(C3:C7) -> 221 | D8: =SUM(D3:D7) -> 136 | E8: =SUM(E3:E7) -> 301 | F8: =SUM(F3:F7) -> 175 | G8: =SUM(G3:G7) -> 126 | H8: =SUM(H3:H7) -> 259 | I8: =SUM(I3:I7) -> 155 | ... S8: =SUM(S3:S7) -> 24
A12: Backlog Details
A13: SECTION | B13: TOTAL | C13: BOYS | D13: GIRLS | E13: Total Students without backlogs | F13: BOYS | G13: GIRLS | H13: Total students with backlog | I13: Boys | J13: Girls | K13: Total Students having 1 backlog | L13: Boys | M13: Girls | N13: Total Students having 2 backlog | O13: Boys | P13: Girls | Q13: Total Students having more than 2 backlog | R13: Boys | S13: Girls
A14: A | B14: =COUNTIF('Analysis data'!$C:$C,$A$3) -> 72 | C14: =COUNTIFS('Analysis data'!$C:$C,$A$3,'Analysis data'!$H:$H,"male") -> 47 | D14: =COUNTIFS('Analysis data'!$C:$C,$A$3,'Analysis data'!$H:$H,"female") -> 25 | E14: =COUNTIFS('Analysis data'!$C:$C,$A$3,'Analysis data'!$G:$G,"pass") -> 59 | F14: =COUNTIFS('Analysis data'!$C:$C,$A$3,'Analysis data'!$H:$H,"male",'Analysis data'!$G:$G,"pass") -> 37 | G14: =COUNTIFS('Analysis data'!$C:$C,$A$3,'Analysis data'!$H:$H,"female",'Analysis data'!$G:$G,"pass") -> 22 | H14: =COUNTIFS('Analysis data'!$C:$C,$A$3,'Analysis data'!$F:$F,"<>0") -> 13 | I14: =COUNTIFS('Analysis data'!$C:$C,$A$3,'Analysis data'!$F:$F,"<>0",'Analysis data'!$H:$H,"male") -> 10 | J14: =COUNTIFS('Analysis data'!$C:$C,$A$3,'Analysis data'!$F:$F,"<>0",'Analysis data'!$H:$H,"female") -> 3 | K14: =COUNTIFS('Analysis data'!$C:$C,$A$3,'Analysis data'!$F:$F,"1") -> 7 | L14: =COUNTIFS('Analysis data'!$C:$C,$A$3,'Analysis data'!$F:$F,"1",'Analysis data'!$H:$H,"male") -> 6 | M14: =COUNTIFS('Analysis data'!$C:$C,$A$3,'Analysis data'!$F:$F,"1",'Analysis data'!$H:$H,"female") -> 1 | N14: =COUNTIFS('Analysis data'!$C:$C,$A$3,'Analysis data'!$F:$F,"2") -> 2 | O14: =COUNTIFS('Analysis data'!$C:$C,$A$3,'Analysis data'!$F:$F,"2",'Analysis data'!$H:$H,"male") -> 2 | P14: =COUNTIFS('Analysis data'!$C:$C,$A$3,'Analysis data'!$F:$F,"2",'Analysis data'!$H:$H,"female") -> 0 | Q14: =COUNTIFS('Analysis data'!$C:$C,$A$3,'Analysis data'!$F:$F,">2") -> 4 | R14: =COUNTIFS('Analysis data'!$C:$C,$A$3,'Analysis data'!$F:$F,">2",'Analysis data'!$H:$H,"male") -> 2 | S14: =COUNTIFS('Analysis data'!$C:$C,$A$3,'Analysis data'!$F:$F,">2",'Analysis data'!$H:$H,"female") -> 2
A15: B | B15: =COUNTIF('Analysis data'!$C:$C,$A$4) -> 72 | C15: =COUNTIFS('Analysis data'!$C:$C,$A$4,'Analysis data'!$H:$H,"male") -> 44 | D15: =COUNTIFS('Analysis data'!$C:$C,$A$4,'Analysis data'!$H:$H,"female") -> 28 | E15: =COUNTIFS('Analysis data'!$C:$C,$A$4,'Analysis data'!$G:$G,"pass") -> 60 | F15: =COUNTIFS('Analysis data'!$C:$C,$A$4,'Analysis data'!$H:$H,"male",'Analysis data'!$G:$G,"pass") -> 33 | G15: =COUNTIFS('Analysis data'!$C:$C,$A$4,'Analysis data'!$H:$H,"female",'Analysis data'!$G:$G,"pass") -> 27 | H15: =COUNTIFS('Analysis data'!$C:$C,$A$4,'Analysis data'!$F:$F,"<>0") -> 11 | I15: =COUNTIFS('Analysis data'!$C:$C,$A$4,'Analysis data'!$F:$F,"<>0",'Analysis data'!$H:$H,"male") -> 10 | J15: =COUNTIFS('Analysis data'!$C:$C,$A$4,'Analysis data'!$F:$F,"<>0",'Analysis data'!$H:$H,"female") -> 1 | K15: =COUNTIFS('Analysis data'!$C:$C,$A$4,'Analysis data'!$F:$F,"1") -> 5 | L15: =COUNTIFS('Analysis data'!$C:$C,$A$4,'Analysis data'!$F:$F,"1",'Analysis data'!$H:$H,"male") -> 4 | M15: =COUNTIFS('Analysis data'!$C:$C,$A$4,'Analysis data'!$F:$F,"1",'Analysis data'!$H:$H,"female") -> 1 | N15: =COUNTIFS('Analysis data'!$C:$C,$A$4,'Analysis data'!$F:$F,"2") -> 2 | O15: =COUNTIFS('Analysis data'!$C:$C,$A$4,'Analysis data'!$F:$F,"2",'Analysis data'!$H:$H,"male") -> 2 | P15: =COUNTIFS('Analysis data'!$C:$C,$A$4,'Analysis data'!$F:$F,"2",'Analysis data'!$H:$H,"female") -> 0 | Q15: =COUNTIFS('Analysis data'!$C:$C,$A$4,'Analysis data'!$F:$F,">2") -> 4 | R15: =COUNTIFS('Analysis data'!$C:$C,$A$4,'Analysis data'!$F:$F,">2",'Analysis data'!$H:$H,"male") -> 4 | S15: =COUNTIFS('Analysis data'!$C:$C,$A$4,'Analysis data'!$F:$F,">2",'Analysis data'!$H:$H,"female") -> 0
A16: C | B16: =COUNTIF('Analysis data'!$C:$C,$A$5) -> 71 | C16: =COUNTIFS('Analysis data'!$C:$C,$A$5,'Analysis data'!$H:$H,"male") -> 49 | D16: =COUNTIFS('Analysis data'!$C:$C,$A$5,'Analysis data'!$H:$H,"female") -> 22 | E16: =COUNTIFS('Analysis data'!$C:$C,$A$5,'Analysis data'!$G:$G,"pass") -> 57 | F16: =COUNTIFS('Analysis data'!$C:$C,$A$5,'Analysis data'!$H:$H,"male",'Analysis data'!$G:$G,"pass") -> 38 | G16: =COUNTIFS('Analysis data'!$C:$C,$A$5,'Analysis data'!$H:$H,"female",'Analysis data'!$G:$G,"pass") -> 19 | H16: =COUNTIFS('Analysis data'!$C:$C,$A$5,'Analysis data'!$F:$F,"<>0") -> 14 | I16: =COUNTIFS('Analysis data'!$C:$C,$A$5,'Analysis data'!$F:$F,"<>0",'Analysis data'!$H:$H,"male") -> 11 | J16: =COUNTIFS('Analysis data'!$C:$C,$A$5,'Analysis data'!$F:$F,"<>0",'Analysis data'!$H:$H,"female") -> 3 | K16: =COUNTIFS('Analysis data'!$C:$C,$A$5,'Analysis data'!$F:$F,"1") -> 8 | L16: =COUNTIFS('Analysis data'!$C:$C,$A$5,'Analysis data'!$F:$F,"1",'Analysis data'!$H:$H,"male") -> 6 | M16: =COUNTIFS('Analysis data'!$C:$C,$A$5,'Analysis data'!$F:$F,"1",'Analysis data'!$H:$H,"female") -> 2 | N16: =COUNTIFS('Analysis data'!$C:$C,$A$5,'Analysis data'!$F:$F,"2") -> 1 | O16: =COUNTIFS('Analysis data'!$C:$C,$A$5,'Analysis data'!$F:$F,"2",'Analysis data'!$H:$H,"male") -> 1 | P16: =COUNTIFS('Analysis data'!$C:$C,$A$5,'Analysis data'!$F:$F,"2",'Analysis data'!$H:$H,"female") -> 0 | Q16: =COUNTIFS('Analysis data'!$C:$C,$A$5,'Analysis data'!$F:$F,">2") -> 5 | R16: =COUNTIFS('Analysis data'!$C:$C,$A$5,'Analysis data'!$F:$F,">2",'Analysis data'!$H:$H,"male") -> 4 | S16: =COUNTIFS('Analysis data'!$C:$C,$A$5,'Analysis data'!$F:$F,">2",'Analysis data'!$H:$H,"female") -> 1
A17: D | B17: =COUNTIF('Analysis data'!$C:$C,$A$6) -> 71 | C17: =COUNTIFS('Analysis data'!$C:$C,$A$6,'Analysis data'!$H:$H,"male") -> 37 | D17: =COUNTIFS('Analysis data'!$C:$C,$A$6,'Analysis data'!$H:$H,"female") -> 34 | E17: =COUNTIFS('Analysis data'!$C:$C,$A$6,'Analysis data'!$G:$G,"pass") -> 63 | F17: =COUNTIFS('Analysis data'!$C:$C,$A$6,'Analysis data'!$H:$H,"male",'Analysis data'!$G:$G,"pass") -> 31 | G17: =COUNTIFS('Analysis data'!$C:$C,$A$6,'Analysis data'!$H:$H,"female",'Analysis data'!$G:$G,"pass") -> 32 | H17: =COUNTIFS('Analysis data'!$C:$C,$A$6,'Analysis data'!$F:$F,"<>0") -> 8 | I17: =COUNTIFS('Analysis data'!$C:$C,$A$6,'Analysis data'!$F:$F,"<>0",'Analysis data'!$H:$H,"male") -> 6 | J17: =COUNTIFS('Analysis data'!$C:$C,$A$6,'Analysis data'!$F:$F,"<>0",'Analysis data'!$H:$H,"female") -> 2 | K17: =COUNTIFS('Analysis data'!$C:$C,$A$6,'Analysis data'!$F:$F,"1") -> 4 | L17: =COUNTIFS('Analysis data'!$C:$C,$A$6,'Analysis data'!$F:$F,"1",'Analysis data'!$H:$H,"male") -> 2 | M17: =COUNTIFS('Analysis data'!$C:$C,$A$6,'Analysis data'!$F:$F,"1",'Analysis data'!$H:$H,"female") -> 2 | N17: =COUNTIFS('Analysis data'!$C:$C,$A$6,'Analysis data'!$F:$F,"2") -> 1 | O17: =COUNTIFS('Analysis data'!$C:$C,$A$6,'Analysis data'!$F:$F,"2",'Analysis data'!$H:$H,"male") -> 1 | P17: =COUNTIFS('Analysis data'!$C:$C,$A$6,'Analysis data'!$F:$F,"2",'Analysis data'!$H:$H,"female") -> 0 | Q17: =COUNTIFS('Analysis data'!$C:$C,$A$6,'Analysis data'!$F:$F,">2") -> 3 | R17: =COUNTIFS('Analysis data'!$C:$C,$A$6,'Analysis data'!$F:$F,">2",'Analysis data'!$H:$H,"male") -> 3 | S17: =COUNTIFS('Analysis data'!$C:$C,$A$6,'Analysis data'!$F:$F,">2",'Analysis data'!$H:$H,"female") -> 0
A18: E | B18: =COUNTIF('Analysis data'!$C:$C,$A$7) -> 71 | C18: =COUNTIFS('Analysis data'!$C:$C,$A$7,'Analysis data'!$H:$H,"male") -> 44 | D18: =COUNTIFS('Analysis data'!$C:$C,$A$7,'Analysis data'!$H:$H,"female") -> 27 | E18: =COUNTIFS('Analysis data'!$C:$C,$A$7,'Analysis data'!$G:$G,"pass") -> 62 | F18: =COUNTIFS('Analysis data'!$C:$C,$A$7,'Analysis data'!$H:$H,"male",'Analysis data'!$G:$G,"pass") -> 36 | G18: =COUNTIFS('Analysis data'!$C:$C,$A$7,'Analysis data'!$H:$H,"female",'Analysis data'!$G:$G,"pass") -> 26 | H18: =COUNTIFS('Analysis data'!$C:$C,$A$7,'Analysis data'!$F:$F,"<>0") -> 9 | I18: =COUNTIFS('Analysis data'!$C:$C,$A$7,'Analysis data'!$F:$F,"<>0",'Analysis data'!$H:$H,"male") -> 8 | J18: =COUNTIFS('Analysis data'!$C:$C,$A$7,'Analysis data'!$F:$F,"<>0",'Analysis data'!$H:$H,"female") -> 1 | K18: =COUNTIFS('Analysis data'!$C:$C,$A$7,'Analysis data'!$F:$F,"1") -> 4 | L18: =COUNTIFS('Analysis data'!$C:$C,$A$7,'Analysis data'!$F:$F,"1",'Analysis data'!$H:$H,"male") -> 4 | M18: =COUNTIFS('Analysis data'!$C:$C,$A$7,'Analysis data'!$F:$F,"1",'Analysis data'!$H:$H,"female") -> 0 | N18: =COUNTIFS('Analysis data'!$C:$C,$A$7,'Analysis data'!$F:$F,"2") -> 0 | O18: =COUNTIFS('Analysis data'!$C:$C,$A$7,'Analysis data'!$F:$F,"2",'Analysis data'!$H:$H,"male") -> 0 | P18: =COUNTIFS('Analysis data'!$C:$C,$A$7,'Analysis data'!$F:$F,"2",'Analysis data'!$H:$H,"female") -> 0 | Q18: =COUNTIFS('Analysis data'!$C:$C,$A$7,'Analysis data'!$F:$F,">2") -> 5 | R18: =COUNTIFS('Analysis data'!$C:$C,$A$7,'Analysis data'!$F:$F,">2",'Analysis data'!$H:$H,"male") -> 4 | S18: =COUNTIFS('Analysis data'!$C:$C,$A$7,'Analysis data'!$F:$F,">2",'Analysis data'!$H:$H,"female") -> 1
B19: =SUM(B14:B18) -> 357 | C19: =SUM(C14:C18) -> 221 | D19: =SUM(D14:D18) -> 136 | E19: =SUM(E14:E18) -> 301 | F19: =SUM(F14:F18) -> 175 | G19: =SUM(G14:G18) -> 126 | H19: =SUM(H14:H18) -> 55 | I19: =SUM(I14:I18) -> 45 | ... S19: =SUM(S14:S18) -> 4
A22: Management | H22: Convenor
A23: SECTION | B23: TOTAL | C23: BOYS | D23: GIRLS | H23: SECTION | I23: TOTAL | J23: BOYS | K23: GIRLS
A24: A | B24: =COUNTIFS('Analysis data'!$C:$C,$A$3,'Analysis data'!$I:$I,$F$25) -> 19 | C24: =COUNTIFS('Analysis data'!$C:$C,$A$3,'Analysis data'!$H:$H,"male",'Analysis data'!$I:$I,$F$25) -> 14 | D24: =COUNTIFS('Analysis data'!$C:$C,$A$3,'Analysis data'!$H:$H,"female",'Analysis data'!$I:$I,$F$25) -> 5 | F24: Convener | H24: A | I24: =COUNTIFS('Analysis data'!$C:$C,$A$3,'Analysis data'!$I:$I,$F$24) -> 53 | J24: =COUNTIFS('Analysis data'!$C:$C,$A$3,'Analysis data'!$H:$H,"male",'Analysis data'!$I:$I,$F$24) -> 33 | K24: =COUNTIFS('Analysis data'!$C:$C,$A$3,'Analysis data'!$H:$H,"female",'Analysis data'!$I:$I,$F$24) -> 20
A25: B | B25: =COUNTIFS('Analysis data'!$C:$C,$A$4,'Analysis data'!$I:$I,$F$25) -> 23 | C25: =COUNTIFS('Analysis data'!$C:$C,$A$4,'Analysis data'!$H:$H,"male",'Analysis data'!$I:$I,$F$25) -> 16 | D25: =COUNTIFS('Analysis data'!$C:$C,$A$4,'Analysis data'!$H:$H,"female",'Analysis data'!$I:$I,$F$25) -> 7 | F25: Management | H25: B | I25: =COUNTIFS('Analysis data'!$C:$C,$A$4,'Analysis data'!$I:$I,$F$24) -> 48 | J25: =COUNTIFS('Analysis data'!$C:$C,$A$4,'Analysis data'!$H:$H,"male",'Analysis data'!$I:$I,$F$24) -> 27 | K25: =COUNTIFS('Analysis data'!$C:$C,$A$4,'Analysis data'!$H:$H,"female",'Analysis data'!$I:$I,$F$24) -> 21
A26: C | B26: =COUNTIFS('Analysis data'!$C:$C,$A$5,'Analysis data'!$I:$I,$F$25) -> 22 | C26: =COUNTIFS('Analysis data'!$C:$C,$A$5,'Analysis data'!$H:$H,"male",'Analysis data'!$I:$I,$F$25) -> 15 | D26: =COUNTIFS('Analysis data'!$C:$C,$A$5,'Analysis data'!$H:$H,"female",'Analysis data'!$I:$I,$F$25) -> 7 | H26: C | I26: =COUNTIFS('Analysis data'!$C:$C,$A$5,'Analysis data'!$I:$I,$F$24) -> 49 | J26: =COUNTIFS('Analysis data'!$C:$C,$A$5,'Analysis data'!$H:$H,"male",'Analysis data'!$I:$I,$F$24) -> 34 | K26: =COUNTIFS('Analysis data'!$C:$C,$A$5,'Analysis data'!$H:$H,"female",'Analysis data'!$I:$I,$F$24) -> 15
A27: D | B27: =COUNTIFS('Analysis data'!$C:$C,$A$6,'Analysis data'!$I:$I,$F$25) -> 19 | C27: =COUNTIFS('Analysis data'!$C:$C,$A$6,'Analysis data'!$H:$H,"male",'Analysis data'!$I:$I,$F$25) -> 8 | D27: =COUNTIFS('Analysis data'!$C:$C,$A$6,'Analysis data'!$H:$H,"female",'Analysis data'!$I:$I,$F$25) -> 11 | H27: D | I27: =COUNTIFS('Analysis data'!$C:$C,$A$6,'Analysis data'!$I:$I,$F$24) -> 52 | J27: =COUNTIFS('Analysis data'!$C:$C,$A$6,'Analysis data'!$H:$H,"male",'Analysis data'!$I:$I,$F$24) -> 29 | K27: =COUNTIFS('Analysis data'!$C:$C,$A$6,'Analysis data'!$H:$H,"female",'Analysis data'!$I:$I,$F$24) -> 23
A28: E | B28: =COUNTIFS('Analysis data'!$C:$C,$A$7,'Analysis data'!$I:$I,$F$25) -> 15 | C28: =COUNTIFS('Analysis data'!$C:$C,$A$7,'Analysis data'!$H:$H,"male",'Analysis data'!$I:$I,$F$25) -> 12 | D28: =COUNTIFS('Analysis data'!$C:$C,$A$7,'Analysis data'!$H:$H,"female",'Analysis data'!$I:$I,$F$25) -> 3 | H28: E | I28: =COUNTIFS('Analysis data'!$C:$C,$A$7,'Analysis data'!$I:$I,$F$24) -> 55 | J28: =COUNTIFS('Analysis data'!$C:$C,$A$7,'Analysis data'!$H:$H,"male",'Analysis data'!$I:$I,$F$24) -> 31 | K28: =COUNTIFS('Analysis data'!$C:$C,$A$7,'Analysis data'!$H:$H,"female",'Analysis data'!$I:$I,$F$24) -> 24
B29: =SUM(B24:B28) -> 98 | C29: =SUM(C24:C28) -> 65 | D29: =SUM(D24:D28) -> 33 | I29: =SUM(I24:I28) -> 257 | J29: =SUM(J24:J28) -> 154 | K29: =SUM(K24:K28) -> 103
A31: SECTION | B31: ELIGIBLE | C31: BOYS | D31: GIRLS | H31: SECTION | I31: ELIGIBLE | J31: BOYS | K31: GIRLS
A32: A | B32: =COUNTIFS('Analysis data'!$C:$C,$A$3,'Analysis data'!$G:$G,"pass",'Analysis data'!$I:$I,$F$25) -> 12 | C32: =COUNTIFS('Analysis data'!$C:$C,$A$3,'Analysis data'!$H:$H,"male",'Analysis data'!$G:$G,"pass",'Analysis data'!$I:$I,$F$25) -> 9 | D32: =COUNTIFS('Analysis data'!$C:$C,$A$3,'Analysis data'!$H:$H,"female",'Analysis data'!$G:$G,"pass",'Analysis data'!$I:$I,$F$25) -> 3 | H32: A | I32: =COUNTIFS('Analysis data'!$C:$C,$A$3,'Analysis data'!$G:$G,"pass",'Analysis data'!$I:$I,$F$24) -> 47 | J32: =COUNTIFS('Analysis data'!$C:$C,$A$3,'Analysis data'!$H:$H,"male",'Analysis data'!$G:$G,"pass",'Analysis data'!$I:$I,$F$24) -> 28 | K32: =COUNTIFS('Analysis data'!$C:$C,$A$3,'Analysis data'!$H:$H,"female",'Analysis data'!$G:$G,"pass",'Analysis data'!$I:$I,$F$24) -> 19
A33: B | B33: =COUNTIFS('Analysis data'!$C:$C,$A$4,'Analysis data'!$G:$G,"pass",'Analysis data'!$I:$I,$F$25) -> 19 | C33: =COUNTIFS('Analysis data'!$C:$C,$A$4,'Analysis data'!$H:$H,"male",'Analysis data'!$G:$G,"pass",'Analysis data'!$I:$I,$F$25) -> 12 | D33: =COUNTIFS('Analysis data'!$C:$C,$A$4,'Analysis data'!$H:$H,"female",'Analysis data'!$G:$G,"pass",'Analysis data'!$I:$I,$F$25) -> 7 | H33: B | I33: =COUNTIFS('Analysis data'!$C:$C,$A$4,'Analysis data'!$G:$G,"pass",'Analysis data'!$I:$I,$F$24) -> 40 | J33: =COUNTIFS('Analysis data'!$C:$C,$A$4,'Analysis data'!$H:$H,"male",'Analysis data'!$G:$G,"pass",'Analysis data'!$I:$I,$F$24) -> 20 | K33: =COUNTIFS('Analysis data'!$C:$C,$A$4,'Analysis data'!$H:$H,"female",'Analysis data'!$G:$G,"pass",'Analysis data'!$I:$I,$F$24) -> 20
A34: C | B34: =COUNTIFS('Analysis data'!$C:$C,$A$5,'Analysis data'!$G:$G,"pass",'Analysis data'!$I:$I,$F$25) -> 17 | C34: =COUNTIFS('Analysis data'!$C:$C,$A$5,'Analysis data'!$H:$H,"male",'Analysis data'!$G:$G,"pass",'Analysis data'!$I:$I,$F$25) -> 11 | D34: =COUNTIFS('Analysis data'!$C:$C,$A$5,'Analysis data'!$H:$H,"female",'Analysis data'!$G:$G,"pass",'Analysis data'!$I:$I,$F$25) -> 6 | H34: C | I34: =COUNTIFS('Analysis data'!$C:$C,$A$5,'Analysis data'!$G:$G,"pass",'Analysis data'!$I:$I,$F$24) -> 40 | J34: =COUNTIFS('Analysis data'!$C:$C,$A$5,'Analysis data'!$H:$H,"male",'Analysis data'!$G:$G,"pass",'Analysis data'!$I:$I,$F$24) -> 27 | K34: =COUNTIFS('Analysis data'!$C:$C,$A$5,'Analysis data'!$H:$H,"female",'Analysis data'!$G:$G,"pass",'Analysis data'!$I:$I,$F$24) -> 13
A35: D | B35: =COUNTIFS('Analysis data'!$C:$C,$A$6,'Analysis data'!$G:$G,"pass",'Analysis data'!$I:$I,$F$25) -> 18 | C35: =COUNTIFS('Analysis data'!$C:$C,$A$6,'Analysis data'!$H:$H,"male",'Analysis data'!$G:$G,"pass",'Analysis data'!$I:$I,$F$25) -> 8 | D35: =COUNTIFS('Analysis data'!$C:$C,$A$6,'Analysis data'!$H:$H,"female",'Analysis data'!$G:$G,"pass",'Analysis data'!$I:$I,$F$25) -> 10 | H35: D | I35: =COUNTIFS('Analysis data'!$C:$C,$A$6,'Analysis data'!$G:$G,"pass",'Analysis data'!$I:$I,$F$24) -> 45 | J35: =COUNTIFS('Analysis data'!$C:$C,$A$6,'Analysis data'!$H:$H,"male",'Analysis data'!$G:$G,"pass",'Analysis data'!$I:$I,$F$24) -> 23 | K35: =COUNTIFS('Analysis data'!$C:$C,$A$6,'Analysis data'!$H:$H,"female",'Analysis data'!$G:$G,"pass",'Analysis data'!$I:$I,$F$24) -> 22
A36: E | B36: =COUNTIFS('Analysis data'!$C:$C,$A$7,'Analysis data'!$G:$G,"pass",'Analysis data'!$I:$I,$F$25) -> 12 | C36: =COUNTIFS('Analysis data'!$C:$C,$A$7,'Analysis data'!$H:$H,"male",'Analysis data'!$G:$G,"pass",'Analysis data'!$I:$I,$F$25) -> 9 | D36: =COUNTIFS('Analysis data'!$C:$C,$A$7,'Analysis data'!$H:$H,"female",'Analysis data'!$G:$G,"pass",'Analysis data'!$I:$I,$F$25) -> 3 | H36: E | I36: =COUNTIFS('Analysis data'!$C:$C,$A$7,'Analysis data'!$G:$G,"pass",'Analysis data'!$I:$I,$F$24) -> 49 | J36: =COUNTIFS('Analysis data'!$C:$C,$A$7,'Analysis data'!$H:$H,"male",'Analysis data'!$G:$G,"pass",'Analysis data'!$I:$I,$F$24) -> 26 | K36: =COUNTIFS('Analysis data'!$C:$C,$A$7,'Analysis data'!$H:$H,"female",'Analysis data'!$G:$G,"pass",'Analysis data'!$I:$I,$F$24) -> 23
B37: =SUM(B32:B36) -> 78 | C37: =SUM(C32:C36) -> 49 | D37: =SUM(D32:D36) -> 29 | I37: =SUM(I32:I36) -> 221 | J37: =SUM(J32:J36) -> 124 | K37: =SUM(K32:K36) -> 97
A40: SECTION | B40: PLACED UNIQUE | C40: BOYS | D40: GIRLS | H40: SECTION | I40: PLACED UNIQUE | J40: BOYS | K40: GIRLS
A41: A | B41: =COUNTIFS('Analysis data'!$C:$C,$A$3,'Analysis data'!$L:$L,"<>0",'Analysis data'!$I:$I,$F$25) -> 12 | C41: =COUNTIFS('Analysis data'!$C:$C,$A$3,'Analysis data'!$L:$L,"<>0",'Analysis data'!$H:$H,"male",'Analysis data'!$I:$I,$F$25) -> 10 | D41: =COUNTIFS('Analysis data'!$C:$C,$A$3,'Analysis data'!$L:$L,"<>0",'Analysis data'!$H:$H,"FEmale",'Analysis data'!$I:$I,$F$25) -> 2 | H41: A | I41: =COUNTIFS('Analysis data'!$C:$C,$A$3,'Analysis data'!$L:$L,"<>0",'Analysis data'!$I:$I,$F$24) -> 41 | J41: =COUNTIFS('Analysis data'!$C:$C,$A$3,'Analysis data'!$L:$L,"<>0",'Analysis data'!$H:$H,"male",'Analysis data'!$I:$I,$F$24) -> 26 | K41: =COUNTIFS('Analysis data'!$C:$C,$A$3,'Analysis data'!$L:$L,"<>0",'Analysis data'!$H:$H,"FEmale",'Analysis data'!$I:$I,$F$24) -> 15
A42: B | B42: =COUNTIFS('Analysis data'!$C:$C,$A$4,'Analysis data'!$L:$L,"<>0",'Analysis data'!$I:$I,$F$25) -> 16 | C42: =COUNTIFS('Analysis data'!$C:$C,$A$4,'Analysis data'!$L:$L,"<>0",'Analysis data'!$H:$H,"male",'Analysis data'!$I:$I,$F$25) -> 10 | D42: =COUNTIFS('Analysis data'!$C:$C,$A$4,'Analysis data'!$L:$L,"<>0",'Analysis data'!$H:$H,"FEmale",'Analysis data'!$I:$I,$F$25) -> 6 | H42: B | I42: =COUNTIFS('Analysis data'!$C:$C,$A$4,'Analysis data'!$L:$L,"<>0",'Analysis data'!$I:$I,$F$24) -> 34 | J42: =COUNTIFS('Analysis data'!$C:$C,$A$4,'Analysis data'!$L:$L,"<>0",'Analysis data'!$H:$H,"male",'Analysis data'!$I:$I,$F$24) -> 19 | K42: =COUNTIFS('Analysis data'!$C:$C,$A$4,'Analysis data'!$L:$L,"<>0",'Analysis data'!$H:$H,"FEmale",'Analysis data'!$I:$I,$F$24) -> 15
A43: C | B43: =COUNTIFS('Analysis data'!$C:$C,$A$5,'Analysis data'!$L:$L,"<>0",'Analysis data'!$I:$I,$F$25) -> 15 | C43: =COUNTIFS('Analysis data'!$C:$C,$A$5,'Analysis data'!$L:$L,"<>0",'Analysis data'!$H:$H,"male",'Analysis data'!$I:$I,$F$25) -> 9 | D43: =COUNTIFS('Analysis data'!$C:$C,$A$5,'Analysis data'!$L:$L,"<>0",'Analysis data'!$H:$H,"FEmale",'Analysis data'!$I:$I,$F$25) -> 6 | H43: C | I43: =COUNTIFS('Analysis data'!$C:$C,$A$5,'Analysis data'!$L:$L,"<>0",'Analysis data'!$I:$I,$F$24) -> 39 | J43: =COUNTIFS('Analysis data'!$C:$C,$A$5,'Analysis data'!$L:$L,"<>0",'Analysis data'!$H:$H,"male",'Analysis data'!$I:$I,$F$24) -> 27 | K43: =COUNTIFS('Analysis data'!$C:$C,$A$5,'Analysis data'!$L:$L,"<>0",'Analysis data'!$H:$H,"FEmale",'Analysis data'!$I:$I,$F$24) -> 12
A44: D | B44: =COUNTIFS('Analysis data'!$C:$C,$A$6,'Analysis data'!$L:$L,"<>0",'Analysis data'!$I:$I,$F$25) -> 13 | C44: =COUNTIFS('Analysis data'!$C:$C,$A$6,'Analysis data'!$L:$L,"<>0",'Analysis data'!$H:$H,"male",'Analysis data'!$I:$I,$F$25) -> 6 | D44: =COUNTIFS('Analysis data'!$C:$C,$A$6,'Analysis data'!$L:$L,"<>0",'Analysis data'!$H:$H,"FEmale",'Analysis data'!$I:$I,$F$25) -> 7 | H44: D | I44: =COUNTIFS('Analysis data'!$C:$C,$A$6,'Analysis data'!$L:$L,"<>0",'Analysis data'!$I:$I,$F$24) -> 36 | J44: =COUNTIFS('Analysis data'!$C:$C,$A$6,'Analysis data'!$L:$L,"<>0",'Analysis data'!$H:$H,"male",'Analysis data'!$I:$I,$F$24) -> 17 | K44: =COUNTIFS('Analysis data'!$C:$C,$A$6,'Analysis data'!$L:$L,"<>0",'Analysis data'!$H:$H,"FEmale",'Analysis data'!$I:$I,$F$24) -> 19
A45: E | B45: =COUNTIFS('Analysis data'!$C:$C,$A$7,'Analysis data'!$L:$L,"<>0",'Analysis data'!$I:$I,$F$25) -> 12 | C45: =COUNTIFS('Analysis data'!$C:$C,$A$7,'Analysis data'!$L:$L,"<>0",'Analysis data'!$H:$H,"male",'Analysis data'!$I:$I,$F$25) -> 9 | D45: =COUNTIFS('Analysis data'!$C:$C,$A$7,'Analysis data'!$L:$L,"<>0",'Analysis data'!$H:$H,"FEmale",'Analysis data'!$I:$I,$F$25) -> 3 | H45: E | I45: =COUNTIFS('Analysis data'!$C:$C,$A$7,'Analysis data'!$L:$L,"<>0",'Analysis data'!$I:$I,$F$24) -> 40 | J45: =COUNTIFS('Analysis data'!$C:$C,$A$7,'Analysis data'!$L:$L,"<>0",'Analysis data'!$H:$H,"male",'Analysis data'!$I:$I,$F$24) -> 21 | K45: =COUNTIFS('Analysis data'!$C:$C,$A$7,'Analysis data'!$L:$L,"<>0",'Analysis data'!$H:$H,"FEmale",'Analysis data'!$I:$I,$F$24) -> 19
B46: =SUM(B41:B45) -> 68 | C46: =SUM(C41:C45) -> 44 | D46: =SUM(D41:D45) -> 24 | I46: =SUM(I41:I45) -> 190 | J46: =SUM(J41:J45) -> 110 | K46: =SUM(K41:K45) -> 80
A52: SECTION | B52: TOTAL STUDENTS HAVING 9 CGPA | C52: PLACED | D52: UNPLACED
A53: A | B53: =COUNTIFS('Analysis data'!$C:$C,A53,'Analysis data'!$E:$E,">=9") -> 6 | C53: =COUNTIFS('Analysis data'!$C:$C,A53,'Analysis data'!$E:$E,">=9",'Analysis data'!$L:$L,"<>0") -> 6 | D53: =COUNTIFS('Analysis data'!$C:$C,A53,'Analysis data'!$E:$E,">=9",'Analysis data'!$L:$L,"=0") -> 0
...

Sheet Analysis data
A1: Sl. No. | B1: RollNo | C1: Section | D1: Name | E1: CGPA | F1: X | G1: Pass/Fail | H1: Gender | I1: Seat type | J1: Internships | K1: Jobs | L1: Total offers | Q1: Jobs
A2: 1 | B2: 21211A0501 | C2: A | D2: A HRISHIKESH | E2: 8.71 | F2: 0 | G2: =IF(E2>0,"PASS","FAIL") -> PASS | H2: Male | I2: Convener | J2: 0 | K2: TECH MAHINDRA & ASSET10 SOFTWARE | L2: 2 | M2: =IFERROR(__xludf.DUMMYFUNCTION("VLOOKUP(B2,IMPORTRANGE(""1CGZ0Bai7Upqd4o8ih3likiFIYVFcX2B2CZFasZGKRII"",""Refined according to Results!B:J""),9,FALSE)"),8.92) -> 8.92 | O2: =IF(AND(M2=0,N2=0),0,1) -> 1 | Q2: TECH MAHINDRA | W2: {=UNIQUE(Q2:Q358)} -> TECH MAHINDRA | Y2: {=UNIQUE(W:W)}
A3: 2 | B3: 21211A0502 | C3: A | D3: A RAGHAVENDRA | E3: 7.92 | F3: 0 | G3: =IF(E3>0,"PASS","FAIL") -> PASS | H3: Male | I3: Convener | J3: 0 | K3: TECH MAHINDRA & LTI MINDTREE & COGNIZANT-GENC & OPENTEXT | L3: 4 | M3: =IFERROR(__xludf.DUMMYFUNCTION("VLOOKUP(B3,IMPORTRANGE(""1CGZ0Bai7Upqd4o8ih3likiFIYVFcX2B2CZFasZGKRII"",""Refined according to Results!B:J""),9,FALSE)"),7.92) -> 7.92 | Q3: TECH MAHINDRA | W3: Accenture ASE | Y3: TECH MAHINDRA
A4: 3 | B4: 21211A0503 | C4: A | D4: ABBARABOINA SHIVA KUMAR | E4: 8.59 | F4: 0 | G4: =IF(E4>0,"PASS","FAIL") -> PASS | H4: Male | I4: Convener | J4: 0 | K4: Accenture ASE | L4: 1 | M4: =IFERROR(__xludf.DUMMYFUNCTION("VLOOKUP(B4,IMPORTRANGE(""1CGZ0Bai7Upqd4o8ih3likiFIYVFcX2B2CZFasZGKRII"",""Refined according to Results!B:J""),9,FALSE)"),8.71) -> 8.71 | Q4: Accenture ASE | W4: 0 | Y4: Accenture ASE
A5: 4 | B5: 21211A0504 | C5: A | D5: ABHINAV VARMA VEGESNA | F5: 2 | G5: =IF(E5>0,"PASS","FAIL") -> FAIL | H5: Male | I5: Management | J5: 0 | L5: =LEN(H5)-LEN(SUBSTITUTE(H5," & "," ")) -> 0 | M5: =IFERROR(__xludf.DUMMYFUNCTION("VLOOKUP(B5,IMPORTRANGE(""1CGZ0Bai7Upqd4o8ih3likiFIYVFcX2B2CZFasZGKRII"",""Refined according to Results!B:J""),9,FALSE)"),"") | Q5: 0 | W5: MODAK | Y5: 0
A6: 5 | B6: 21211A0505 | C6: A | D6: ACHAMPETA SONALI | E6: 9.01 | F6: 0 | G6: =IF(E6>0,"PASS","FAIL") -> PASS | H6: Female | I6: Convener | J6: DBS | K6: Accenture ASE & TECH MAHINDRA | L6: 2 | M6: =IFERROR(__xludf.DUMMYFUNCTION("VLOOKUP(B6,IMPORTRANGE(""1CGZ0Bai7Upqd4o8ih3likiFIYVFcX2B2CZFasZGKRII"",""Refined according to Results!B:J""),9,FALSE)"),9.1) -> 9.1 | Q6: Accenture ASE | R6: TECH MAHINDRA | W6: LTI Mindtree | Y6: MODAK
A7: 6 | B7: 21211A0506 | C7: A | D7: ADANGI SADHWIK | E7: 8.17 | F7: 0 | G7: =IF(E7>0,"PASS","FAIL") -> PASS | H7: Male | I7: Convener | J7: 0 | K7: Accenture ASE & TECH MAHINDRA | L7: 2 | M7: =IFERROR(__xludf.DUMMYFUNCTION("VLOOKUP(B7,IMPORTRANGE(""1CGZ0Bai7Upqd4o8ih3likiFIYVFcX2B2CZFasZGKRII"",""Refined according to Results!B:J""),9,FALSE)"),8.4) -> 8.4 | Q7: Accenture ASE | R7: TECH MAHINDRA | W7: KPIT | Y7: LTI Mindtree
A8: 7 | B8: 21211A0507 | C8: A | D8: ADEPU SAI RAHUL | E8: 8.99 | F8: 0 | G8: =IF(E8>0,"PASS","FAIL") -> PASS | H8: Male | I8: Convener | J8: 0 | K8: Accenture ASE | L8: 1 | M8: =IFERROR(__xludf.DUMMYFUNCTION("VLOOKUP(B8,IMPORTRANGE(""1CGZ0Bai7Upqd4o8ih3likiFIYVFcX2B2CZFasZGKRII"",""Refined according to Results!B:J""),9,FALSE)"),9.37) -> 9.37 | Q8: Accenture ASE | W8: FRUGAL TESTING | Y8: KPIT
A9: 8 | B9: 21211A0508 | C9: A | D9: ADHAM AKASH | E9: 6.94 | F9: 0 | G9: =IF(E9>0,"PASS","FAIL") -> PASS | H9: Male | I9: Convener | J9: 0 | L9: =LEN(H9)-LEN(SUBSTITUTE(H9," & "," ")) -> 0 | M9: =IFERROR(__xludf.DUMMYFUNCTION("VLOOKUP(B9,IMPORTRANGE(""1CGZ0Bai7Upqd4o8ih3likiFIYVFcX2B2CZFasZGKRII"",""Refined according to Results!B:J""),9,FALSE)"),7.24) -> 7.24 | Q9: 0 | W9: Accenture ADV ASE | Y9: FRUGAL TESTING
A10: 9 | B10: 21211A0509 | C10: A | D10: ADIYALA MADHUMITHA | E10: 8.69 | F10: 0 | G10: =IF(E10>0,"PASS","FAIL") -> PASS | H10: Female | I10: Convener | J10: 0 | L10: =LEN(H10)-LEN(SUBSTITUTE(H10," & "," ")) -> 0 | M10: =IFERROR(__xludf.DUMMYFUNCTION("VLOOKUP(B10,IMPORTRANGE(""1CGZ0Bai7Upqd4o8ih3likiFIYVFcX2B2CZFasZGKRII"",""Refined according to Results!B:J""),9,FALSE)"),8.56) -> 8.56 | Q10: 0 | W10: STATESTREET | Y10: Accenture ADV ASE
A11: 10 | B11: 21211A0510 | C11: A | D11: AGNESH KUNDU | E11: 9.22 | F11: 0 | G11: =IF(E11>0,"PASS","FAIL") -> PASS | H11: Male | I11: Convener | J11: 0 | K11: MODAK & OPTUM & RNTBCI | L11: 3 | M11: =IFERROR(__xludf.DUMMYFUNCTION("VLOOKUP(B11,IMPORTRANGE(""1CGZ0Bai7Upqd4o8ih3likiFIYVFcX2B2CZFasZGKRII"",""Refined according to Results!B:J""),9,FALSE)"),9.35) -> 9.35 | Q11: MODAK | R11: OPTUM | W11: BIGWORKS | Y11: STATESTREET
A12: 11 | B12: 21211A0511 | C12: A | D12: AILENI SREETHIKESH REDDY | F12: 1 | G12: =IF(E12>0,"PASS","FAIL") -> FAIL | H12: Male | I12: Management | J12: 0 | K12: TECH MAHINDRA & CORIZO-BDA | L12: 2 | M12: =IFERROR(__xludf.DUMMYFUNCTION("VLOOKUP(B12,IMPORTRANGE(""1CGZ0Bai7Upqd4o8ih3likiFIYVFcX2B2CZFasZGKRII"",""Refined according to Results!B:J""),9,FALSE)"),"") | Q12: TECH MAHINDRA | W12: OPTUM | Y12: BIGWORKS
A13: 12 | B13: 21211A0512 | C13: A | D13: AILINENI VEDA SRI | E13: 8.43 | F13: 0 | G13: =IF(E13>0,"PASS","FAIL") -> PASS | H13: Female | I13: Convener | J13: 0 | K13: Accenture ASE & OPTUM & LTI MINDTREE | L13: 3 | M13: =IFERROR(__xludf.DUMMYFUNCTION("VLOOKUP(B13,IMPORTRANGE(""1CGZ0Bai7Upqd4o8ih3likiFIYVFcX2B2CZFasZGKRII"",""Refined according to Results!B:J""),9,FALSE)"),8.6) -> 8.6 | Q13: Accenture ASE | R13: OPTUM | S13: LTI Mindtree | W13: VERISK-1 | Y13: OPTUM
A14: 13 | B14: 21211A0513 | C14: A | D14: AJMEERA SINDHUJA | E14: 7.78 | F14: 0 | G14: =IF(E14>0,"PASS","FAIL") -> PASS | H14: Female | I14: Convener | J14: 0 | K14: SEOAK | L14: 1 | M14: =IFERROR(__xludf.DUMMYFUNCTION("VLOOKUP(B14,IMPORTRANGE(""1CGZ0Bai7Upqd4o8ih3likiFIYVFcX2B2CZFasZGKRII"",""Refined according to Results!B:J""),9,FALSE)"),7.69) -> 7.69 | Q14: 0 | W14: INFOSYS-HWI | Y14: VERISK-1
A15: 14 | B15: 21211A0514 | C15: A | D15: AKULA VYSHNAVI | E15: 8.04 | F15: 0 | G15: =IF(E15>0,"PASS","FAIL") -> PASS | H15: Female | I15: Convener | J15: 0 | K15: SEOAK | L15: 1 | M15: =IFERROR(__xludf.DUMMYFUNCTION("VLOOKUP(B15,IMPORTRANGE(""1CGZ0Bai7Upqd4o8ih3likiFIYVFcX2B2CZFasZGKRII"",""Refined according to Results!B:J""),9,FALSE)"),7.94) -> 7.94 | Q15: 0 | W15: VIAPLUS | Y15: INFOSYS-HWI
A16: 15 | B16: 21211A0515 | C16: A | D16: AMAND SRI SIDDHARTHA | E16: 8.47 | F16: 0 | G16: =IF(E16>0,"PASS","FAIL") -> PASS | H16: Male | I16: Convener | J16: HEXAGONE & Realpage | K16: Accenture ASE & TECH MAHINDRA & LTI MINDTREE & REALPAGE1 | L16: 4 | M16: =IFERROR(__xludf.DUMMYFUNCTION("VLOOKUP(B16,IMPORTRANGE(""1CGZ0Bai7Upqd4o8ih3likiFIYVFcX2B2CZFasZGKRII"",""Refined according to Results!B:J""),9,FALSE)"),8.62) -> 8.62 | Q16: Accenture ASE | R16: TECH MAHINDRA | S16: LTI Mindtree | W16: SOTI | Y16: VIAPLUS
A17: 16 | B17: 21211A0516 | C17: A | D17: AMBATI SAHITHI | E17: 8.79 | F17: 0 | G17: =IF(E17>0,"PASS","FAIL") -> PASS | H17: Female | I17: Management | J17: 0 | K17: Accenture ASE & TECH MAHINDRA & OPTUM & RNTBCI | L17: 4 | M17: =IFERROR(__xludf.DUMMYFUNCTION("VLOOKUP(B17,IMPORTRANGE(""1CGZ0Bai7Upqd4o8ih3likiFIYVFcX2B2CZFasZGKRII"",""Refined according to Results!B:J""),9,FALSE)"),8.79) -> 8.79 | Q17: Accenture ASE | R17: TECH MAHINDRA | S17: OPTUM | W17: BANK OF AMERICA | Y17: SOTI
A18: 17 | B18: 21211A0517 | C18: A | D18: MAHTO | E18: 8.78 | F18: 0 | G18: =IF(E18>0,"PASS","FAIL") -> PASS | H18: Female | I18: Convener | J18: 0 | K18: Accenture ASE | L18: 1 | M18: =IFERROR(__xludf.DUMMYFUNCTION("VLOOKUP(B18,IMPORTRANGE(""1CGZ0Bai7Upqd4o8ih3likiFIYVFcX2B2CZFasZGKRII"",""Refined according to Results!B:J""),9,FALSE)"),8.54) -> 8.54 | Q18: Accenture ASE | W18: INFOSYS-1 | Y18: BANK OF AMERICA
A19: 18 | B19: 21211A0518 | C19: A | D19: ANNAPUREDDY ARUN KUMAR REDDY | F19: 1 | G19: =IF(E19>0,"PASS","FAIL") -> FAIL | H19: Male | I19: Convener | J19: 0 | L19: =LEN(H19)-LEN(SUBSTITUTE(H19," & "," ")) -> 0 | M19: =IFERROR(__xludf.DUMMYFUNCTION("VLOOKUP(B19,IMPORTRANGE(""1CGZ0Bai7Upqd4o8ih3likiFIYVFcX2B2CZFasZGKRII"",""Refined according to Results!B:J""),9,FALSE)"),6.45) -> 6.45 | Q19: 0 | W19: {=UNIQUE(R6:R358)} -> TECH MAHINDRA | Y19: INFOSYS-1
A20: 19 | B20: 21211A0519 | C20: A | D20: ANTHAREDDY TANVI REDDY | F20: 1 | G20: =IF(E20>0,"PASS","FAIL") -> FAIL | H20: Female | I20: Management | J20: 0 | L20: =LEN(H20)-LEN(SUBSTITUTE(H20," & "," ")) -> 0 | M20: =IFERROR(__xludf.DUMMYFUNCTION("VLOOKUP(B20,IMPORTRANGE(""1CGZ0Bai7Upqd4o8ih3likiFIYVFcX2B2CZFasZGKRII"",""Refined according to Results!B:J""),9,FALSE)"),8.12) -> 8.12 | Q20: 0 | Y20: PORTER-SDE1
A21: 20 | B21: 21211A0520 | C21: A | D21: AREPUDI VINAY KUMAR | E21: 8.41 | F21: 0 | G21: =IF(E21>0,"PASS","FAIL") -> PASS | H21: Male | I21: Convener | J21: 0 | K21: MRF | L21: 1 | M21: =IFERROR(__xludf.DUMMYFUNCTION("VLOOKUP(B21,IMPORTRANGE(""1CGZ0Bai7Upqd4o8ih3likiFIYVFcX2B2CZFasZGKRII"",""Refined according to Results!B:J""),9,FALSE)"),8.31) -> 8.31 | Q21: 0 | W21: OPTUM | Y21: PORTER-SDE-TEST
A22: 21 | B22: 21211A0521 | C22: A | D22: ASOORI MURALI KRISHNA | E22: 8.42 | F22: 0 | G22: =IF(E22>0,"PASS","FAIL") -> PASS | H22: Male | I22: Management | J22: 0 | K22: TECH MAHINDRA & VEEVA-SQL | L22: 2 | M22: =IFERROR(__xludf.DUMMYFUNCTION("VLOOKUP(B22,IMPORTRANGE(""1CGZ0Bai7Upqd4o8ih3likiFIYVFcX2B2CZFasZGKRII"",""Refined according to Results!B:J""),9,FALSE)"),8.6) -> 8.6 | Q22: TECH MAHINDRA | W22: Accenture ASE | Y22: FACTSET
A23: 22 | B23: 21211A0522 | C23: A | D23: ABBARAJU VENKATA NAGA SAI KARTIK | E23: 8.15 | F23: 0 | G23: =IF(E23>0,"PASS","FAIL") -> PASS | H23: Male | I23: Management | J23: 0 | K23: LTI MINDTREE & INFOSYS-SE | L23: 2 | M23: =IFERROR(__xludf.DUMMYFUNCTION("VLOOKUP(B23,IMPORTRANGE(""1CGZ0Bai7Upqd4o8ih3likiFIYVFcX2B2CZFasZGKRII"",""Refined according to Results!B:J""),9,FALSE)"),7.97) -> 7.97 | Q23: LTI Mindtree | W23: LTI Mindtree
A24: 23 | B24: 21211A0523 | C24: A | D24: AVULA THARUN | E24: 9.16 | F24: 0 | G24: =IF(E24>0,"PASS","FAIL") -> PASS | H24: Male | I24: Convener | J24: 0 | K24: Accenture ASE & INFOSYS1-SE | L24: 2 | M24: =IFERROR(__xludf.DUMMYFUNCTION("VLOOKUP(B24,IMPORTRANGE(""1CGZ0Bai7Upqd4o8ih3likiFIYVFcX2B2CZFasZGKRII"",""Refined according to Results!B:J""),9,FALSE)"),9.42) -> 9.42 | Q24: Accenture ASE | W24: INFOSYS-1
A25: 24 | B25: 21211A0524 | C25: A | D25: BADAVATHKRISHNAVENI | F25: 3 | G25: =IF(E25>0,"PASS","FAIL") -> FAIL | H25: Female | I25: Convener | J25: 0 | L25: =LEN(H25)-LEN(SUBSTITUTE(H25," & "," ")) -> 0 | M25: =IFERROR(__xludf.DUMMYFUNCTION("VLOOKUP(B25,IMPORTRANGE(""1CGZ0Bai7Upqd4o8ih3likiFIYVFcX2B2CZFasZGKRII"",""Refined according to Results!B:J""),9,FALSE)"),"") | Q25: 0 | W25: KPIT
A26: 25 | B26: 21211A0525 | C26: A | D26: BALAVARI VANESSA THANMAYI | E26: 8.58 | F26: 0 | G26: =IF(E26>0,"PASS","FAIL") -> PASS | H26: Female | I26: Convener | J26: 0 | K26: Accenture ASE & TECH MAHINDRA & CAPGEMINI-ANALYST | L26: 3 | M26: =IFERROR(__xludf.DUMMYFUNCTION("VLOOKUP(B26,IMPORTRANGE(""1CGZ0Bai7Upqd4o8ih3likiFIYVFcX2B2CZFasZGKRII"",""Refined according to Results!B:J""),9,FALSE)"),8.73) -> 8.73 | Q26: Accenture ASE | R26: TECH MAHINDRA | W26: BANK OF AMERICA
A27: 26 | B27: 21211A0526 | C27: A | D27: BANDANADAM PRANAYA | E27: 8.65 | F27: 0 | G27: =IF(E27>0,"PASS","FAIL") -> PASS | H27: Female | I27: Convener | J27: 0 | K27: RNTBCI & INFOSYS-OFFCAMPUS-SE | L27: 2 | M27: =IFERROR(__xludf.DUMMYFUNCTION("VLOOKUP(B27,IMPORTRANGE(""1CGZ0Bai7Upqd4o8ih3likiFIYVFcX2B2CZFasZGKRII"",""Refined according to Results!B:J""),9,FALSE)"),8.71) -> 8.71 | Q27: 0 | W27: VIAPLUS
A28: 27 | B28: 21211A0527 | C28: A | D28: BANDARI RAMCHARAN | E28: 8.25 | F28: 0 | G28: =IF(E28>0,"PASS","FAIL") -> PASS | H28: Male | I28: Convener | J28: 0 | K28: OPENTEXT | L28: 1 | M28: =IFERROR(__xludf.DUMMYFUNCTION("VLOOKUP(B28,IMPORTRANGE(""1CGZ0Bai7Upqd4o8ih3likiFIYVFcX2B2CZFasZGKRII"",""Refined according to Results!B:J""),9,FALSE)"),8.63) -> 8.63 | Q28: 0 | W28: PORTER-SDE1
A29: 28 | B29: 21211A0528 | C29: A | D29: BANDARI SAIJYOTHI | E29: 8.4 | F29: 0 | G29: =IF(E29>0,"PASS","FAIL") -> PASS | H29: Female | I29: Convener | J29: 0 | K29: KPIT & COGNIZANT-GENC | L29: 2 | M29: =IFERROR(__xludf.DUMMYFUNCTION("VLOOKUP(B29,IMPORTRANGE(""1CGZ0Bai7Upqd4o8ih3likiFIYVFcX2B2CZFasZGKRII"",""Refined according to Results!B:J""),9,FALSE)"),8.18) -> 8.18 | Q29: KPIT | W29: {=UNIQUE(S13:S358)} -> LTI Mindtree
A30: 29 | B30: 21211A0529 | C30: A | D30: BATHULA VENKATA RAMANA | E30: 8.14 | F30: 0 | G30: =IF(E30>0,"PASS","FAIL") -> PASS | H30: Male | I30: Convener | J30: 0 | K30: Accenture ASE | L30: 1 | M30: =IFERROR(__xludf.DUMMYFUNCTION("VLOOKUP(B30,IMPORTRANGE(""1CGZ0Bai7Upqd4o8ih3likiFIYVFcX2B2CZFasZGKRII"",""Refined according to Results!B:J""),9,FALSE)"),8.56) -> 8.56 | Q30: Accenture ASE
A31: 30 | B31: 21211A0530 | C31: A | D31: BAVANTHULA ANUDEEP REDDY | E31: 8.74 | F31: 0 | G31: =IF(E31>0,"PASS","FAIL") -> PASS | H31: Male | I31: Convener | J31: 0 | K31: MODAK & Accenture ASE | L31: 2 | M31: =IFERROR(__xludf.DUMMYFUNCTION("VLOOKUP(B31,IMPORTRANGE(""1CGZ0Bai7Upqd4o8ih3likiFIYVFcX2B2CZFasZGKRII"",""Refined according to Results!B:J""),9,FALSE)"),8.99) -> 8.99 | Q31: MODAK | R31: Accenture ASE | W31: OPTUM
A32: 31 | B32: 21211A0531 | C32: A | D32: BAVIRTI SURYA SAI KIRAN REKHA | E32: 8.6 | F32: 0 | G32: =IF(E32>0,"PASS","FAIL") -> PASS | H32: Female | I32: Convener | J32: 0 | K32: KPIT | L32: 1 | M32: =IFERROR(__xludf.DUMMYFUNCTION("VLOOKUP(B32,IMPORTRANGE(""1CGZ0Bai7Upqd4o8ih3likiFIYVFcX2B2CZFasZGKRII"",""Refined according to Results!B:J""),9,FALSE)"),8.74) -> 8.74 | Q32: KPIT | W32: TECH MAHINDRA
A33: 32 | B33: 21211A0532 | C33: A | D33: BEGARI RAGHAVI | E33: 8.35 | F33: 0 | G33: =IF(E33>0,"PASS","FAIL") -> PASS | H33: Female | I33: Convener | J33: 0 | K33: Accenture ASE | L33: 1 | M33: =IFERROR(__xludf.DUMMYFUNCTION("VLOOKUP(B33,IMPORTRANGE(""1CGZ0Bai7Upqd4o8ih3likiFIYVFcX2B2CZFasZGKRII"",""Refined according to Results!B:J""),9,FALSE)"),8.46) -> 8.46 | Q33: Accenture ASE | W33: KPIT
A34: 33 | B34: 21211A0533 | C34: A | D34: BEJUGAM SAITEJA | E34: 8.42 | F34: 0 | G34: =IF(E34>0,"PASS","FAIL") -> PASS | H34: Male | I34: Management | J34: 0 | K34: Accenture ASE & INFOSYS-OFFCAMPUS-SE | L34: 2 | M34: =IFERROR(__xludf.DUMMYFUNCTION("VLOOKUP(B34,IMPORTRANGE(""1CGZ0Bai7Upqd4o8ih3likiFIYVFcX2B2CZFasZGKRII"",""Refined according to Results!B:J""),9,FALSE)"),8.35) -> 8.35 | Q34: Accenture ASE | W34: STATESTREET
A35: 34 | B35: 21211A0534 | C35: A | D35: BETHI ANIRUDH REDDY | E35: 7.29 | F35: 0 | G35: =IF(E35>0,"PASS","FAIL") -> PASS | H35: Male | I35: Management | J35: 0 | K35: CAPGEMINI-ANALYST | L35: 1 | M35: =IFERROR(__xludf.DUMMYFUNCTION("VLOOKUP(B35,IMPORTRANGE(""1CGZ0Bai7Upqd4o8ih3likiFIYVFcX2B2CZFasZGKRII"",""Refined according to Results!B:J""),9,FALSE)"),7.14) -> 7.14 | Q35: 0 | W35: PORTER-SDE-TEST
A36: 35 | B36: 21211A0535 | C36: A | D36: SASIKANTH REDDY BHIMIREDDY | E36: 8.19 | F36: 0 | G36: =IF(E36>0,"PASS","FAIL") -> PASS | H36: Male | I36: Management | J36: 0 | K36: CORIZO-BDA & SEOAK & COGNIZANT-OFF CAMPUS | L36: 3 | M36: =IFERROR(__xludf.DUMMYFUNCTION("VLOOKUP(B36,IMPORTRANGE(""1CGZ0Bai7Upqd4o8ih3likiFIYVFcX2B2CZFasZGKRII"",""Refined according to Results!B:J""),9,FALSE)"),8.15) -> 8.15 | Q36: 0 | W36: FACTSET
A37: 36 | B37: 21211A0536 | C37: A | D37: BOLIBOTHULA VARUN | F37: 16 | G37: =IF(E37>0,"PASS","FAIL") -> FAIL | H37: Male | I37: Management | J37: 0 | L37: =LEN(H37)-LEN(SUBSTITUTE(H37," & "," ")) -> 0 | M37: =IFERROR(__xludf.DUMMYFUNCTION("VLOOKUP(B37,IMPORTRANGE(""1CGZ0Bai7Upqd4o8ih3likiFIYVFcX2B2CZFasZGKRII"",""Refined according to Results!B:J""),9,FALSE)"),"") | Q37: 0 | W37: BANK OF AMERICA
A38: 37 | B38: 21211A0537 | C38: A | D38: BOLLAM MANIDEEP | E38: 7.75 | F38: 0 | G38: =IF(E38>0,"PASS","FAIL") -> PASS | H38: Male | I38: Convener | J38: 0 | L38: =LEN(H38)-LEN(SUBSTITUTE(H38," & "," ")) -> 0 | M38: =IFERROR(__xludf.DUMMYFUNCTION("VLOOKUP(B38,IMPORTRANGE(""1CGZ0Bai7Upqd4o8ih3likiFIYVFcX2B2CZFasZGKRII"",""Refined according to Results!B:J""),9,FALSE)"),7.65) -> 7.65 | Q38: 0 | W38: {=UNIQUE(T47:T358)}
A39: 38 | B39: 21211A0538 | C39: A | D39: BOMMENA ARAVIND | E39: 7.69 | F39: 0 | G39: =IF(E39>0,"PASS","FAIL") -> PASS | H39: Male | I39: Convener | J39: 0 | K39: SEOAK & MRF | L39: 2 | M39: =IFERROR(__xludf.DUMMYFUNCTION("VLOOKUP(B39,IMPORTRANGE(""1CGZ0Bai7Upqd4o8ih3likiFIYVFcX2B2CZFasZGKRII"",""Refined according to Results!B:J""),9,FALSE)"),7.45) -> 7.45 | Q39: 0 | W39: OPTUM
A40: 39 | B40: 21211A0539 | C40: A | D40: BOMMISHETTT VAMSHI | F40: 1 | G40: =IF(E40>0,"PASS","FAIL") -> FAIL | H40: Male | I40: Convener | J40: 0 | L40: =LEN(H40)-LEN(SUBSTITUTE(H40," & "," ")) -> 0 | M40: =IFERROR(__xludf.DUMMYFUNCTION("VLOOKUP(B40,IMPORTRANGE(""1CGZ0Bai7Upqd4o8ih3likiFIYVFcX2B2CZFasZGKRII"",""Refined according to Results!B:J""),9,FALSE)"),7.85) -> 7.85 | Q40: 0 | W40: LTI Mindtree
...

Sheet Company WISE data
A1: SNO | B1: Company Name | C1: Mode of Engagement | D1: Date of selection (mm/dd/yy) | E1: Total Fulltime Selects | F1: Salary (Rs. LPA) | G1: Total Internship Selects | H1: Stipend (Rs. p.m.) | I1: Unique | J1: Multiple
A2: 1 | B2: DELOITTE | C2: Internship | D2: 45215 | E2: 0 | G2: 2 | H2: 15000 | I2: 0 | J2: =G2-I2 -> 2
A3: 2 | B3: DBS | C3: Internship | D3: 45404 | E3: 0 | G3: 9 | H3: 36000 | I3: 1 | J3: =G3-I3 -> 8
A4: 3 | B4: NITK | C4: Internship | D4: 45428 | E4: 0 | G4: 1 | I4: 0 | J4: =G4-I4 -> 1
A5: 4 | B5: HEXAGONE | C5: Internship | D5: 45429 | E5: 0 | G5: 3 | H5: 25000 | I5: 0 | J5: =G5-I5 -> 3
A6: 5 | B6: MICROSOFT | C6: Internship | D6: 45433 | E6: 0 | G6: 1 | H6: 125000 | I6: 0 | J6: =G6-I6 -> 1
A7: 6 | B7: INFOSYS-HWI | C7: Fulltime | D7: 45446 | E7: 1 | F7: 9.5 | G7: 0 | I7: 0 | J7: 1
A8: 7 | B8: FORAGE AI | C8: Internship | D8: 45456 | E8: 0 | G8: 3 | H8: 10000 | I8: 2 | J8: =G8-I8 -> 1
A9: 8 | B9: MODAK | C9: Fulltime | D9: 45516 | E9: 11 | F9: 6 | G9: 0 | I9: 4 | J9: =E9-I9 -> 7
A10: 9 | B10: HUB DATA - IIIT HYDERABAD | C10: Internship | D10: 45139 | E10: 0 | G10: 1 | H10: 10000 | I10: 0 | J10: =G10-I10 -> 1
A11: 10 | B11: VERISK-1 | C11: Fulltime | D11: 45518 | E11: 4 | F11: 10 | G11: 0 | I11: 3 | J11: =E11-I11 -> 1
A12: 11 | B12: National Institute of the Empowerment of People with Intellectual Disabilities, Secunderabad | C12: Internship | D12: 45518 | E12: 0 | G12: 2 | I12: 0 | J12: =G12-I12 -> 2
A13: 12 | B13: SENTIANTAL IT SOFTWARE SOLUTIONS-OFF CAMPUS | C13: Internship | D13: 45523 | E13: 0 | G13: 1 | H13: 15000 | I13: 0 | J13: =G13-I13 -> 1
A14: 13 | B14: FRUGAL TESTING | C14: PPO | D14: 45530 | E14: 1 | F14: 8 | G14: 1 | H14: 10000 | I14: 1 | J14: =E14-I14 -> 0
A15: 14 | B15: STATESTREET | C15: PPO | D15: 45559 | E15: 4 | F15: 8.6 | G15: 4 | H15: 30000 | I15: 1 | J15: =E15-I15 -> 3
A16: 15 | B16: ACCENTURE ASE | C16: Fulltime | D16: 45565 | E16: 101 | F16: 4.5 | G16: 0 | I16: 32 | J16: =E16-I16 -> 69
A17: 16 | B17: ACCENTURE ADV ASE | C17: Fulltime | D17: 45565 | E17: 1 | F17: 6.5 | G17: 0 | I17: 0 | J17: =E17-I17 -> 1
A18: 17 | B18: VIAPLUS | C18: PPO | D18: 45566 | E18: 3 | F18: 7 | G18: 3 | H18: 30000 | I18: 1 | J18: =E18-I18 -> 2
A19: 18 | B19: SOTI | C19: Fulltime | D19: 45569 | E19: 1 | F19: 7.5 | G19: 0 | I19: 0 | J19: =E19-I19 -> 1
A20: 19 | B20: TECH MAHINDRA | C20: Fulltime | D20: 45576 | E20: 51 | F20: 5.5 | G20: 0 | I20: 6 | J20: =E20-I20 -> 45
A21: 20 | B21: OPENTEXT | C21: PPO | D21: 45580 | E21: 19 | F21: 11 | I21: 2 | J21: =E21-I21 -> 17 | M21: 19
A22: 21 | B22: INFOSYS-1 | C22: Fulltime | D22: 45582 | E22: 2 | F22: 9.5 | G22: 0 | I22: 0 | J22: =E22-I22 -> 2
A23: 22 | B23: PORTER-SDE1 | C23: PPO | D23: 45582 | E23: 2 | F23: 17 | G23: 2 | H23: 80000 | I23: 0 | J23: =E23-I23 -> 2
A24: 23 | B24: PORTER-SDE-TEST | C24: PPO | D24: 45582 | E24: 1 | F24: 13 | G24: 1 | H24: 50000 | I24: 0 | J24: =E24-I24 -> 1
A25: 24 | B25: BANK OF AMERICA | C25: Fulltime | D25: 45587 | E25: 4 | F25: 6.45 | G25: 0 | I25: 0 | J25: =E25-I25 -> 4
A26: 25 | B26: OPTUM | C26: Fulltime | D26: 45588 | E26: 19 | F26: 18.56 | I26: 2 | J26: =E26-I26 -> 17
A27: 26 | B27: RNTBCI | C27: Fulltime | D27: 45599 | E27: 13 | F27: 4.25 | I27: 0 | J27: =E27-I27 -> 13
A28: 27 | B28: EPAM | C28: PPO | D28: 45610 | E28: 1 | F28: 8 | G28: 1 | H28: 25000 | I28: 0 | J28: =E28-I28 -> 1
A29: 28 | B29: FACTSET | C29: PPO | D29: 45614 | E29: 1 | F29: 10 | G29: 1 | H29: 30000 | I29: 0 | J29: =E29-I29 -> 1
A30: 29 | B30: KPIT | C30: Fulltime | D30: 45614 | E30: 8 | F30: 4.4 | G30: 0 | I30: 1 | J30: =E30-I30 -> 7
A31: 30 | B31: BIGWORKS | C31: Fulltime | D31: 45612 | E31: 4 | F31: 4 | G31: 0 | I31: 0 | J31: =E31-I31 -> 4
A32: 31 | B32: LTI MINDTREE | C32: Fulltime | D32: 45618 | E32: 53 | F32: 4.05 | G32: 0 | I32: 7 | J32: =E32-I32 -> 46
A33: 32 | B33: INFOSYS-SE | C33: Fulltime | D33: 45618 | E33: 28 | F33: 3.6 | G33: 0 | I33: 16 | J33: =E33-I33 -> 12
A34: 33 | B34: BRISTOL MYERS SQUIBB | C34: Fulltime | D34: 45622 | E34: 1 | F34: 8.8 | G34: 0 | I34: 0 | J34: =E34-I34 -> 1
A35: 34 | B35: COGNIZANT-GENC | C35: Fulltime | D35: 45628 | E35: 34 | F35: 4 | G35: 0 | I35: 4 | J35: =E35-I35 -> 30
A36: 35 | B36: AMAZON-SDE INTERN | C36: Internship | D36: 45628 | E36: 0 | G36: 1 | H36: 110000 | I36: 0 | J36: =G36-I36 -> 1
A37: 36 | B37: INFOSYS-2 | C37: Fulltime | D37: 45632 | E37: 1 | F37: 9.5 | G37: 0 | I37: 0 | J37: =E37-I37 -> 1
A38: 37 | B38: ZELIS | C38: PPO | D38: 45640 | E38: 1 | F38: 5 | G38: 1 | H38: 25000 | I38: 1 | J38: =E38-I38 -> 0
A39: 38 | B39: SKILL DUNIYA | C39: PPO | D39: 45640 | E39: 12 | F39: 3.5 | G39: 12 | H39: 15000 | I39: 7 | J39: =E39-I39 -> 5
A40: 39 | B40: CORIZO1-BOE | C40: Fulltime | D40: 45646 | E40: 1 | F40: 4 | G40: 0 | I40: 0 | J40: =E40-I40 -> 1
...

Sheet complete data UG 2025
A1: S No | B1: Roll NO | C1: FNAME | D1: LNAME | E1: Name | G1: UID | H1: Pega | I1: APT-1 | J1: APT-2 | K1: APT-3 | L1: Special Training | M1: EAMCET | N1: ECET | O1: DOB | P1: Gender | Q1: Branch | R1: 10th % | S1: 10th YOP | T1: Inter / Dip % | U1: Inter YOP | V1: CGPA | W1: B. Tech % | X1: UG YOP | Y1: Active Backlogs (III-I) | Z1: BE History | AA1: College Email ID | AB1: Web email ID | AC1: Phone | AD1: Parent / Alternate Number | AE1: Offers | AF1: Intern | AG1: Address | AH1: Father Name | AI1: I-I CGPA | AJ1: I-II CGPA | AK1: II-I CGPA | AL1: II-II CGPA | AM1: III-I CGPA | AN1: III-II CGPA | AO1: Seat type | AP1: Projects | AQ1: Project Details | AS1: Certifications | AT1: Hosteller / Day Scholar | AU1: Remarks
B2: 21211A0501 | C2: A | D2: HRISHIKESH | E2: A HRISHIKESH | F2: 0 | G2: 557430000000 | H2: - | I2: 1090 | J2: - | K2: - | L2: AI / ML, Data Sciences, Cyber Security, IoT, Block Chain, Python, Big Data, Mobile Applications, Extended Reality (AR / VR) | M2: 11983 | N2: 0 | O2: 24-05-2004 | P2: Male | Q2: CSE | R2: 98 | S2: 2019 | T2: 97.8 | U2: 2021 | V2: 8.65 | W2: 81.5 | X2: 2025 | Y2: 0 | Z2: 0 | AA2: 21211a0501@bvrit.ac.in | AB2: ankamhrishikesh@gmail.com | AC2: 6304816805 | AD2: 9848094847 | AE2: TECH MAHINDRA | AF2: 0 | AG2: Narsapur, Medak | AH2: Ankam Ravinder | AI2: 9.3 | AJ2: 8.59 | AK2: 8.61 | AL2: 0 | AM2: 8.67 | AN2: 8.65 | AO2: Convener | AQ2: : | AT2: Day Scholar
B3: 21211A0502 | C3: A | D3: RAGHAVENDRA | E3: A RAGHAVENDRA | F3: 0 | G3: 793377000000 | H3: - | I3: 793 | J3: - | K3: - | L3: AI / ML, Data Sciences,c++, Java, Python, Mobile Applications, Web Development | M3: 18615 | N3: 0 | O3: 24-10-2003 | P3: Male | Q3: CSE | R3: 78.6 | S3: 2019 | T3: 92.3 | U3: 2021 | V3: 7.88 | W3: 73.8 | X3: 2025 | Y3: 0 | Z3: 0 | AA3: 21211a0502@bvrit.ac.in | AB3: ragharam6262@gmail.com | AC3: 9113214584 | AD3: 8050549769 | AE3: TECH MAHINDRA & LTI MINDTREE & COGNIZANT-GENC | AF3: 0 | AG3: Near brown bear bakery, HMT hills, Jntu, Kphb, Hyderabad - 500085 | AH3: A KOTESWARA RAO | AI3: 7.95 | AJ3: 7.9 | AK3: 7.59 | AL3: 0 | AM3: 7.87 | AN3: 7.88 | AO3: Convener | AQ3: : | AT3: Day Scholar
B4: 21211A0503 | C4: ABBARABOINA | D4: SHIVA KUMAR | E4: ABBARABOINA SHIVA KUMAR | F4: 0 | G4: 822831000000 | H4: - | I4: - | J4: - | K4: - | L4: AI / ML, Data Sciences, Cyber Security, Python, Cloud, Big Data, Mobile Applications, Web Development | M4: 9510 | N4: 0 | O4: 17-02-2004 | P4: Male | Q4: CSE | R4: 98 | S4: 2019 | T4: 98.2 | U4: 2021 | V4: 8.57 | W4: 80.7 | X4: 2025 | Y4: 0 | Z4: 0 | AA4: 21211a0503@bvrit.ac.in | AB4: shivakumarabbaraboina@gmail.com | AC4: 7207874156 | AD4: 9866548969 | AE4: Accenture ASE | AF4: 0 | AG4: 2-98, Akaram Village, Dubbak Mandal, Siddipet District, Telangana. | AH4: SHANKAR | AI4: 8.65 | AJ4: 8.76 | AK4: 8.25 | AL4: 0 | AM4: 8.5 | AN4: 8.57 | AO4: Convener | AQ4: : | AT4: Hosteller
B5: 21211A0504 | C5: ABHINAV VARMA | D5: VEGESNA | E5: ABHINAV VARMA VEGESNA | F5: 0 | G5: 471952000000 | H5: - | I5: - | J5: - | K5: - | L5: AI / ML, Data Sciences, Python | M5: 0 | N5: 0 | O5: 18-06-2003 | P5: Male | Q5: CSE | R5: 65.6 | S5: 2019 | T5: 94 | U5: 2021 | V5: 0 | W5: -5 | X5: 2025 | Y5: 2 | Z5: 4 | AA5: 21211a0504@bvrit.ac.in | AB5: abhinavvarmavegesna@gmail.com | AC5: 7989638007 | AD5: 9989484569 | AE5: 0 | AF5: 0 | AG5: Sri Pavithra recidency ,flat no.401,glr colony near old age home; nizampet | AH5: Venkata Siva Naga Srinivasa raju vegesna | AI5: 0 | AJ5: 0 | AK5: 0 | AL5: 0 | AM5: 5.92 | AN5: 0 | AO5: Management | AQ5: : | AT5: Day Scholar
B6: 21211A0505 | C6: ACHAMPETA | D6: SONALI | E6: ACHAMPETA SONALI | F6: 0 | G6: 763752000000 | H6: - | I6: 817 | J6: - | K6: - | L6: AI / ML, Data Sciences, Cyber Security, IoT, Block Chain, Python, Cloud, Big Data, Mobile Applications, Extended Reality (AR / VR) | M6: 10417 | N6: 0 | O6: 24-04-2004 | P6: Female | Q6: CSE | R6: 97 | S6: 2019 | T6: 96.2 | U6: 2021 | V6: 9.03 | W6: 85.3 | X6: 2025 | Y6: 0 | Z6: 0 | AA6: 21211a0505@bvrit.ac.in | AB6: sonaliachampeta@gmail.com | AC6: 9392288747 | AD6: 9849317523 | AE6: Accenture ASE & TECH MAHINDRA | AF6: DBS | AG6: 202, gurukula apartment ,odf colony ,sangareddy . | AH6: A V G K PRASAD | AI6: 9.35 | AJ6: 8.88 | AK6: 8.59 | AL6: 0 | AM6: 9.02 | AN6: 9.03 | AO6: Convener | AQ6: : | AT6: Day Scholar
B7: 21211A0506 | C7: ADANGI | D7: SADHWIK | E7: ADANGI SADHWIK | F7: 0 | G7: 575172000000 | H7: - | I7: 622 | J7: - | K7: - | L7: AI / ML, Data Sciences, Python, Mobile Applications | M7: 13624 | N7: 0 | O7: 25-01-2004 | P7: Male | Q7: CSE | R7: 97 | S7: 2019 | T7: 98 | U7: 2021 | V7: 8.19 | W7: 76.9 | X7: 2025 | Y7: 0 | Z7: 0 | AA7: 21211a0506@bvrit.ac.in | AB7: sadhwiknani25012004@gmail.com | AC7: 8328144785 | AD7: 8106810384 | AE7: Accenture ASE & TECH MAHINDRA | AF7: 0 | AG7: PLOT NO 80, SRI NILAYAM, PRAGATHINAGAR, KUKATPALLY, HYDERABAD, TELANGANA | AH7: ADANGI ESWARA RAO | AI7: 8.68 | AJ7: 8.15 | AK7: 8.41 | AL7: 0 | AM7: 8.17 | AN7: 8.19 | AO7: Convener | AQ7: : | AT7: Day Scholar
B8: 21211A0507 | C8: ADEPU | D8: SAI RAHUL | E8: ADEPU SAI RAHUL | F8: 0 | G8: 652568000000 | H8: - | I8: 980 | J8: - | K8: - | L8: AI / ML, Cyber Security, Python, WEB DEVELOPMENT | M8: 13864 | N8: 0 | O8: 18-07-2004 | P8: Male | Q8: CSE | R8: 100 | S8: 2019 | T8: 98.8 | U8: 2021 | V8: 9.06 | W8: 85.6 | X8: 2025 | Y8: 0 | Z8: 0 | AA8: 21211a0507@bvrit.ac.in | AB8: sairahuladepu@gmail.com | AC8: 6304690288 | AD8: 9392464449 | AE8: Accenture ASE | AF8: 0 | AG8: 4-37-37, road number 7, RamaKrishna Nagar, Jagathgiri Gutta, Kukatpally, Hyderabad, 500037 | AH8: ADEPU RAMESH BABU | AI8: 9.68 | AJ8: 9.1 | AK8: 8.73 | AL8: 0 | AM8: 9.08 | AN8: 9.06 | AO8: Convener | AQ8: : | AT8: Day Scholar
B9: 21211A0508 | C9: ADHAM | D9: AKASH | E9: ADHAM AKASH | F9: 0 | G9: 468008000000 | H9: - | I9: - | J9: - | K9: - | L9: AI / ML, Data Sciences, Python | M9: 19000 | N9: 0 | O9: 37752 | P9: Male | Q9: CSE | R9: 88 | S9: 2019 | T9: 88 | U9: 2021 | V9: 6.91 | W9: 64.1 | X9: 2025 | Y9: 0 | Z9: 0 | AA9: 21211A0508@bvrit.ac.in | AB9: mittuakash2@gmail.com | AC9: 9959296937 | AD9: 8497973300 | AE9: 0 | AF9: 0 | AG9: Nizamabad,Maruthi nagar, opp kings club | AH9: ADHAM PURUSHOTHAM | AI9: 7.27 | AJ9: 7.22 | AK9: 6.95 | AL9: 0 | AM9: 6.92 | AN9: 6.91 | AO9: Convener | AQ9: : | AT9: Hosteller
B10: 21211A0509 | C10: ADIYALA | D10: MADHUMITHA | E10: ADIYALA MADHUMITHA | F10: 0 | G10: 780590000000 | H10: - | I10: - | J10: - | K10: - | M10: 34431 | N10: 0 | O10: 20-08-2004 | P10: Female | Q10: CSE | R10: 97 | S10: 2019 | T10: 89 | U10: 2021 | V10: 8.65 | W10: 81.5 | X10: 2025 | Y10: 0 | Z10: 0 | AA10: 21211A0509@bvrit.ac.in | AB10: madhumithavenkatreddyadiyala@gmail.com | AC10: 8977532025 | AD10: 8639216585 | AE10: 0 | AF10: 0 | AG10: Punya residency, Springfield colony, Srisai enclave road, jeedimetla,Petbasheerabad | AH10: Adiyala Thara | AI10: 8.76 | AJ10: 8.39 | AK10: 8.86 | AL10: 0 | AM10: 8.65 | AN10: 8.65 | AO10: Convener | AQ10: : | AT10: Day Scholar
